<?xml version="1.0"?>
<robot name="single_leg">

  <link name="base_link">
    <visual>
      <geometry><box size="0.1 0.1 0.1"/></geometry>
      <material name="blue"><color rgba="0 0 1 1"/></material>
    </visual>
  </link>

  <joint name="hip_joint" type="revolute">
    <parent link="base_link"/>
    <child link="coxa_link"/>
    <origin xyz="0 0 0"/>
    <axis xyz="0 0 1"/>
    <limit lower="-1.57" upper="1.57" effort="10" velocity="1"/>
  </joint>

  <link name="coxa_link">
    <visual>
      <origin xyz="0.025 0 0"/>
      <geometry><box size="0.05 0.03 0.03"/></geometry>
    </visual>
  </link>

  <joint name="thigh_joint" type="revolute">
    <parent link="coxa_link"/>
    <child link="femur_link"/>
    <origin xyz="0.05 0 0"/>
    <axis xyz="0 1 0"/>
    <limit lower="-1.57" upper="1.57" effort="10" velocity="1"/>
  </joint>

  <link name="femur_link">
    <visual>
      <origin xyz="0 0 -0.05"/>
      <geometry><box size="0.02 0.02 0.1"/></geometry>
    </visual>
  </link>

  <joint name="knee_joint" type="revolute">
    <parent link="femur_link"/>
    <child link="tibia_link"/>
    <origin xyz="0 0 -0.1"/>
    <axis xyz="0 1 0"/>
    <limit lower="-2.5" upper="0" effort="10" velocity="1"/>
  </joint>

  <link name="tibia_link">
    <visual>
      <origin xyz="0 0 -0.05"/>
      <geometry><box size="0.02 0.02 0.1"/></geometry>
    </visual>
  </link>

</robot>